Workbook

Sheet Resumo da Sprint
A1: RESUMO GERAL DAS SPRINTS — SISTEMA DE GESTÃO DE CONTRATOS
A3: Visão executiva das 4 primeiras sprints do projeto
A5: SPRINTS NO RESUMO | D5: ITENS PLANEJADOS | G5: ITENS ENTREGUES (REG.) | I5: ADERÊNCIA REGISTRADA
A6: 4 | D6: =SUM(B12:B15) -> 41 | G6: =SUM(C12:C15) -> 41 | I6: =IFERROR(SUM(C12:C15)/SUM(B12:B15),0) -> 1
B7: =#ERR520! -> #N/A
E9: =#ERR520! -> #N/A
A10: DESEMPENHO POR SPRINT
A11: Sprint | B11: Planejados | C11: Concluídos | D11: % Concluído | E11: Status | F11: Período
A12: ='Evolução do Projeto'!A5 -> Sprint 0 - 13.07.2026 a 24.07.2026 | B12: ='Evolução do Projeto'!B5 -> 3 | C12: ='Evolução do Projeto'!C5 -> 3 | D12: =IF(C12="", "", IFERROR(C12/B12,0)) -> 1 | E12: =IF(C12="","Atualizar",IF(C12>=B12,"Concluída","Parcial")) -> Concluída | F12: =IFERROR(MID(A12,FIND("-",A12)+2,99),"") -> 13.07.2026 a 24.07.2026
A13: ='Evolução do Projeto'!A6 -> Sprint 1 - 27.07.2026 a 07.08.2026 | B13: 10 | C13: 10 | D13: =IF(C13="", "", IFERROR(C13/B13,0)) -> 1 | E13: =IF(C13="","Atualizar",IF(C13>=B13,"Concluída","Parcial")) -> Concluída | F13: =IFERROR(MID(A13,FIND("-",A13)+2,99),"") -> 27.07.2026 a 07.08.2026
A14: ='Evolução do Projeto'!A7 -> Sprint 2 - 10.08.2026 a 21.08.2026 | B14: 16 | C14: 16 | D14: =IF(C14="", "", IFERROR(C14/B14,0)) -> 1 | E14: =IF(C14="","Atualizar",IF(C14>=B14,"Concluída","Parcial")) -> Concluída | F14: =IFERROR(MID(A14,FIND("-",A14)+2,99),"") -> 10.08.2026 a 21.08.2026
A15: ='Evolução do Projeto'!A8 -> Sprint 3 - 24.08.2026 a 04.09.2026 | B15: ='Evolução do Projeto'!B8 -> 12 | C15: 12 | D15: =IF(C15="", "", IFERROR(C15/B15,0)) -> 1 | E15: =IF(C15="","Atualizar",IF(C15>=B15,"Concluída","Parcial")) -> Concluída | F15: =IFERROR(MID(A15,FIND("-",A15)+2,99),"") -> 24.08.2026 a 04.09.2026
A16: ='Evolução do Projeto'!A9 -> Sprint 4 - 08.09.2026 a 18.09.2026 | B16: ='Evolução do Projeto'!B9 -> 10 | C16: 10 | D16: =IF(C16="", "", IFERROR(C16/B16,0)) -> 1 | E16: =IF(C16="","Atualizar",IF(C16>=B16,"Concluída","Parcial")) -> Concluída | F16: =IFERROR(MID(A16,FIND("-",A16)+2,99),"") -> 08.09.2026 a 18.09.2026
A17: ='Evolução do Projeto'!A10 -> Sprint 5 - 21.09.2026 a 02.10.2026 | B17: ='Evolução do Projeto'!B10 -> 10 | C17: 10 | D17: =IF(C17="", "", IFERROR(C17/B17,0)) -> 1 | E17: =IF(C17="","Atualizar",IF(C17>=B17,"Concluída","Parcial")) -> Concluída | F17: =IFERROR(MID(A17,FIND("-",A17)+2,99),"") -> 21.09.2026 a 02.10.2026
A20: OBSERVAÇÃO DE CONTROLE

Sheet Funcionalidades Entregues
A1: HISTÓRICO DE FUNCIONALIDADES ENTREGUES | I1: RESUMO DAS ENTREGAS
A2: Base acumulada — adicione as entregas de cada nova sprint nas linhas abaixo. | I2: Indicador | J2: Valor
I3: Itens registrados | K3: =COUNTA(B5:B500) -> 65
A4: Sprint | B4: ID | C4: Funcionalidade | D4: Descrição da entrega | E4: Responsável | F4: Status | G4: Observações | I4: Itens entregues | K4: =COUNTIF(F5:F500,"Entregue") -> 0
A5: Sprint 0 - 13.07.2026 a 24.07.2026 | B5: 1947 | C5: Arquitetura | D5: Criar estrutura dos projetos, backend e frontend. | E5: Edvaldo | F5: Feito
A6: Sprint 0 - 13.07.2026 a 24.07.2026 | B6: 1948 | C6: Prototipo | D6: Desenvolvido protótipo navegável usando o framework Angular20, cujo código html será reaproveitado no frontend. | E6: Edvaldo | F6: Feito | I6: Sprint | J6: Qtd. registrada
A7: Sprint 0 - 13.07.2026 a 24.07.2026 | B7: 1949 | C7: Kickoff | D7: Apresentação do KickOff. | E7: Henrique | F7: Feito | I7: Sprint 1 | K7: =COUNTIF(A5:A500,"Sprint 1") -> 0
A8: Sprint 1 - 27.07.2026 a 07.08.2026 | B8: 1961 | C8: Historia de Usuário referente a funcionalidade Manter Usuário. | D8: BDD- Definir o comportamento da funcionalidade em questão e ser reaproveitado na geração de testes automatizados através do framework Cucumber. | E8: Edvaldo | F8: Feito | I8: Sprint 2 | K8: =COUNTIF(A5:A500,"Sprint 2") -> 0
A9: Sprint 1 - 27.07.2026 a 07.08.2026 | B9: 1962 | C9: BackEnd referente a funcionalidade Manter Usuário. | D9: Desenvolvimento de todas as camadas da API Java Spring Boot3. Controller, Service, Repository, DTOs, Exceptions e Validações. | E9: Edvaldo | F9: Feito | I9: Sprint 3 | K9: =COUNTIF(A5:A500,"Sprint 3") -> 0
A10: Sprint 1 - 27.07.2026 a 07.08.2026 | B10: 1963 | C10: FrontEnd referente a funcionalidade Manter Usuário. | D10: Desenvolvimento da CRUD(Create Usuário, Ready Usuario, Update Usuario, Delete e Inative Usuario) referente a funcionalidade em questão. | E10: Edvaldo | F10: Feito | I10: Sprint 4 | K10: =COUNTIF(A5:A500,"Sprint 4") -> 0
A11: Sprint 1 - 27.07.2026 a 07.08.2026 | B11: 1973 | C11: Historia de Usuário referente a funcionalidade Permissões do Usuário. | D11: BDD- Definir o comportamento da funcionalidade em questão e ser reaproveitado na geração de testes automatizados através do framework Cucumber. | E11: Edvaldo | F11: Feito
A12: Sprint 1 - 27.07.2026 a 07.08.2026 | B12: 1974 | C12: BackEnd referente a funcionalidade Login do Usuário. | D12: Desenvolvimento de todas as camadas da API Java Spring Boot3. Controller, Service, Repository, DTOs, Exceptions e Validações. | E12: Edvaldo | F12: Feito
A13: Sprint 1 - 27.07.2026 a 07.08.2026 | B13: 1975 | C13: FrontEnd referente a funcionalidade Login do Usuário. | D13: Desenvolvimento da CRUD(Create Usuário, Ready Usuario, Update Usuario, Delete e Inative Usuario) referente a funcionalidade em questão. | E13: Edvaldo | F13: Feito
A14: Sprint 1 - 27.07.2026 a 07.08.2026 | B14: 1967 | C14: Historia de Usuário referente a funcionalidade Permissões do Usuário. | D14: BDD- Definir o comportamento da funcionalidade em questão e ser reaproveitado na geração de testes automatizados através do framework Cucumber. | E14: Edvaldo | F14: Feito
A15: Sprint 1 - 27.07.2026 a 07.08.2026 | B15: 1968 | C15: BackEnd referente a funcionalidade Permissões do Usuário. | D15: Desenvolvimento de todas as camadas da API Java Spring Boot3. Controller, Service, Repository, DTOs, Exceptions e Validações. | E15: Edvaldo | F15: Feito
A16: Sprint 1 - 27.07.2026 a 07.08.2026 | B16: 1969 | C16: FrontEnd referente a funcionalidade Permissões do Usuário. | D16: Desenvolvimento da CRUD(Create Usuário, Ready Usuario, Update Usuario, Delete e Inative Usuario) referente a funcionalidade em questão. | E16: Edvaldo | F16: Feito
A17: Sprint 1 - 27.07.2026 a 07.08.2026 | B17: 2110 | C17: Gestao de contratos | D17: Refinamento de requisitos | E17: Edvaldo | F17: Feito
A18: Sprint 2 - 10.08.2026 a 21.08.2026 | B18: 1964 | C18: Teste automatizado | D18: Usuario | E18: Edvaldo | F18: Feito
A19: Sprint 2 - 10.08.2026 a 21.08.2026 | B19: 2112 | C19: Projeto de testes | D19: Criar estrutura de testes automatizados Cypress – TR-Novo-Sistema-Contratos | E19: Edvaldo | F19: Feito
A20: Sprint 2 - 10.08.2026 a 21.08.2026 | B20: 1970 | C20: Teste automatizado | D20: Permissões de usuários. | E20: Edvaldo | F20: Feito
A21: Sprint 2 - 10.08.2026 a 21.08.2026 | B21: 1980 | C21: User story | D21: Documento de requisitos Produto | E21: Edvaldo | F21: Feito
A22: Sprint 2 - 10.08.2026 a 21.08.2026 | B22: 1981 | C22: BackEnd referente a funcionalidade manutenção de Produto. | D22: Desenvolvimento de todas as camadas da API Java Spring Boot3. Controller, Service, Repository, DTOs, Exceptions e Validações. | E22: Edvaldo | F22: Feito
A23: Sprint 2 - 10.08.2026 a 21.08.2026 | B23: 1982 | C23: FrontEnd referente a funcionalidade manutenção de Produto. | D23: Desenvolvimento da CRUD(Create Produto, Ready Produto, Update Produto, Delete Produto) referente a funcionalidade em questão. | E23: Edvaldo | F23: Feito
A24: Sprint 2 - 10.08.2026 a 21.08.2026 | B24: 1983 | C24: Teste automatizado | D24: Teste automatizado funcionalidade de produto. | E24: Edvaldo | F24: Feito
A25: Sprint 2 - 10.08.2026 a 21.08.2026 | B25: 2133 | C25: User story | D25: Afinamento de requisitos gestão de contratos. | E25: Edvaldo | F25: Feito
A26: Sprint 2 - 10.08.2026 a 21.08.2026 | B26: 1985 | C26: User story | D26: Documento de requisitos Versões de Produto | E26: Edvaldo | F26: Feito
A27: Sprint 2 - 10.08.2026 a 21.08.2026 | B27: 1986 | C27: BackEnd referente a funcionalidade manutenção de Versões de Produto. | D27: Desenvolvimento de todas as camadas da API Java Spring Boot3. Controller, Service, Repository, DTOs, Exceptions e Validações. | E27: Edvaldo | F27: Feito
A28: Sprint 2 - 10.08.2026 a 21.08.2026 | B28: 1987 | C28: FrontEnd referente a funcionalidade manutenção de Versões Produto. | D28: Desenvolvimento da CRUD(Create Versões do Produto, Ready Versões do Produto, Update Versões do Produto, Delete Versões do Produto) referente a funcionalidade em questão. | E28: Edvaldo | F28: Feito
... A45: Sprint 3 - 24.08.2026 a 04.09.2026 | B45: 2011 | C45: Teste automatizado | D45: Teste automatizado funcionalidade de Clientes | E45: Edvaldo | F45: Feito
A46: Sprint 4 - 08.09.2026 a 18.09.2026 | B46: 2016 | C46: User story | D46: Documento de requisitos CNAE | E46: Edvaldo | F46: Feito
A47: Sprint 4 - 08.09.2026 a 18.09.2026 | B47: 2017 | C47: BackEnd referente a funcionalidade manutenção de CNAE. | D47: Desenvolvimento de todas as camadas da API Java Spring Boot3. Controller, Service, Repository, DTOs, Exceptions e Validações. | E47: Edvaldo | F47: Feito
A48: Sprint 4 - 08.09.2026 a 18.09.2026 | B48: 2018 | C48: FrontEnd referente a funcionalidade manutenção de CNAE. | D48: Desenvolvimento da CRUD(Create CNAE, Ready CNAE, Update CNAE, Delete CNAE) referente a funcionalidade em questão. | E48: Edvaldo | F48: Feito
A49: Sprint 4 - 08.09.2026 a 18.09.2026 | B49: 2019 | C49: User story | D49: Documento de requisitos Industrias | E49: Edvaldo | F49: Feito
A50: Sprint 4 - 08.09.2026 a 18.09.2026 | B50: 2020 | C50: BackEnd referente a funcionalidade manutenção de Industrias. | D50: Desenvolvimento de todas as camadas da API Java Spring Boot3. Controller, Service, Repository, DTOs, Exceptions e Validações. | E50: Edvaldo | F50: Feito
A51: Sprint 4 - 08.09.2026 a 18.09.2026 | B51: 2021 | C51: FrontEnd referente a funcionalidade manutenção de Industrias. | D51: Desenvolvimento da CRUD(Create Industrias, Ready Industrias, Update Industrias, Delete Industrias) referente a funcionalidade em questão. | E51: Edvaldo | F51: Feito
A52: Sprint 4 - 08.09.2026 a 18.09.2026 | B52: 2022 | C52: Testes Automatizados | D52: Teste automatizado funcionalidade de Industrias. | E52: Edvaldo | F52: Feito
A53: Sprint 4 - 08.09.2026 a 18.09.2026 | B53: 2024 | C53: User story | D53: Documento de requisitos ERPS | E53: Edvaldo | F53: Feito
A54: Sprint 4 - 08.09.2026 a 18.09.2026 | B54: 2025 | C54: BackEnd referente a funcionalidade manutenção de ERPS. | D54: Desenvolvimento de todas as camadas da API Java Spring Boot3. Controller, Service, Repository, DTOs, Exceptions e Validações. | E54: Edvaldo | F54: Feito
A55: Sprint 4 - 08.09.2026 a 18.09.2026 | B55: 2026 | C55: FrontEnd referente a funcionalidade manutenção de ERPS. | D55: Desenvolvimento da CRUD(Create ERPS, Ready ERPS, Update ERPS, Delete ERPS) referente a funcionalidade em questão. | E55: Edvaldo | F55: Feito
A56: Sprint 5 - 21.09.2026 a 02.10.2026 | B56: 2030 | C56: User story | D56: Documento de requisitos Indexadores | E56: Edvaldo | F56: Feito
...

Sheet Próxima Sprint
A1: PLANEJAMENTO DA PRÓXIMA SPRINT
A4: Sprint | B4: ID | C4: Funcionalidade | D4: Descrição da entrega | E4: Responsável | F4: Status | G4: Observações | I4: Itens entregues | K4: =COUNTIF(F5:F483,"Entregue") -> 0
A5: Sprint 6 - 05.10.2026 a 16.10.2026 | E5: Edvaldo
E6: Edvaldo
E7: Edvaldo
E8: Felipe
E9: Edvaldo
E10: Edvaldo
E11: Edvaldo
E12: Felipe
E13: Edvaldo
E14: Edvaldo
E15: Edvaldo
E16: Felipe
E17: Edvaldo
E18: Edvaldo

Sheet Pendências e Decisões
A1: PENDÊNCIAS, DÚVIDAS E DECISÕES
A4: ID | B4: Tema | C4: Pergunta / Decisão necessária | D4: Responsável | E4: Prazo Limite | F4: Status | G4: Impacto
A5: PD_01 | B5: Acesso TR – VDI | C5: Liberação da VDI(Edvaldo) por parte da TR | D5: Marcio | E5: 46290 | F5: Resolvido | G5: Alto
A6: PD_02 | B6: Acesso- SnowFlake | C6: Liberação de Acesso por parte da TR | D6: Carlos | E6: 46290 | F6: Resolvido | G6: Alto
A7: PD_03 | B7: Acesso – Power BI | C7: Liberação de Acesso por parte da TR | D7: Carlos | E7: 46290 | F7: Em atraso | G7: Alto
A8: PD_04 | B8: Ambiente QA | C8: Liberação de Ambiente QA para disponibilizar a aplicação | D8: Marcio | E8: 46290 | F8: Em atraso | G8: Alto
A9: PD_05 | B9: Acesso aos Excedentes | C9: Criação de EndPoint para acesso às informações de Excedentes | D9: Alcestes | E9: 46326 | F9: Em análise | G9: Alto
A10: PD_06 | B10: Aprovação dos Fluxos | C10: Aprovação dos 5 primeiros Fluxos de Gestão de Contratos discutidos em reuniões de trabalho | D10: Jaqueline / Sérgio / Michael / Carlos | E10: 46290 | F10: Resolvido | G10: Alto
A11: PD_07 | B11: Fluxo de Entitlement | C11: Após reunião com o time de Entitlement ficou decidido que o time TR - Entitlement iria definir um fluxo de Complementação de Contrato, para apresentação. Similar ao feito pela Bárbara / Dislaine. | D11: Jaqueline / Sérgio / Michael / Carlos | F11: Em análise | G11: Alto

Sheet Evolução do Projeto
A1: EVOLUÇÃO DAS ENTREGAS POR SPRINT
A4: Sprint | B4: Planejadas | C4: Entregues na Sprint | D4: Entregas acumuladas
A5: Sprint 0 - 13.07.2026 a 24.07.2026 | B5: 3 | C5: 3 | D5: =C5 -> 3
A6: Sprint 1 - 27.07.2026 a 07.08.2026 | B6: 10 | C6: 10 | D6: =D5+C6 -> 13
A7: Sprint 2 - 10.08.2026 a 21.08.2026 | B7: 14 | C7: 14 | D7: =D6+C7 -> 27
A8: Sprint 3 - 24.08.2026 a 04.09.2026 | B8: 12 | C8: 12 | D8: =D7+C8 -> 39
A9: Sprint 4 - 08.09.2026 a 18.09.2026 | B9: 10 | C9: 10 | D9: =D8+C9 -> 49
A10: Sprint 5 - 21.09.2026 a 02.10.2026 | B10: 10 | C10: 10 | D10: =D9+C10 -> 59
A11: Sprint 6 - 05.10.2026 a 16.10.2026 | B11: 8 | D11: =D10+C11 -> 59
A12: Sprint 7 - 19.10.2026 a 30.10.2026 | B12: 16 | D12: =D11+C12 -> 59
A13: Sprint 8 - 03.11.2026 a 13.11.2026 | B13: 6 | D13: =D12+C13 -> 59
A14: Sprint 9 - 16.11.2026 a 27.11.2026 | B14: 8 | D14: =D13+C14 -> 59
A15: Sprint 10 - 30.11.2026 a 11.12.2026 | B15: 4 | D15: =D14+C15 -> 59

Sheet Riscos
A1: RISCOS DO PROJETO
A4: ID | B4: Risco | C4: Descrição | D4: Impacto | E4: Probabilidade | F4: Mitigação | G4: Responsável | H4: Status
A5: RI_01 | B5: Dependência de acessos TR – VDI) | C5: Para que não ocorra atrasos no desenvolvimento, o acesso VDI de desenvolvimento precisa esta liberada o mais rapido possível. | D5: Alto | E5: Alta | F5: Priorizar liberações com a TR e manter ambiente local de desenvolvimento | G5: Marcio | H5: Resolvido
A6: RI_02 | B6: Dependência de acessos TR Snowflake | C6: Para que não ocorra atrasos no desenvolvimento, o acesso ao SnowFlake tem que esta disponivel no maximo ate 28.09.2026, uma vez que o desenvolvimento que se inicia em 05.10 depende estudo já pronto para a integração | D6: Alto | E6: Alta | F6: Priorizar liberações com a TR e manter ambiente local/mock enquanto pendente. | G6: Marcio | H6: Resolvido
A7: RI_03 | B7: Dependência de acessos TR Power BI | C7: Para que não ocorra atrasos no desenvolvimento, o acesso ao Power BI tem que esta disponivel no maximo ate 28.09.2026, uma vez que o desenvolvimento que se inicia em 05.10 depende estudo já pronto para a integração | D7: Alto | E7: Alta | F7: Priorizar liberações com a TR e manter ambiente local/mock enquanto pendente. | G7: Marcio | H7: Aberto
A8: RI_04 | B8: Ambiente QA indisponível | C8: Sem QA, a disponibilização da aplicação para homologação fica bloqueada. | D8: Alto | E8: Alta | F8: Acompanhar liberação do ambiente e validar checklist de deploy antecipadamente. | G8: Marcio | H8: Aberto
A9: RI_05 | B9: Regras de negócios apresentando indefinições | C9: Durante o levantamento dos requisitos do Sistema de Contratos, identificamos alguns pontos que ainda estão sendo discutidos e que possuem diferentes entendimentos sobre as regras de negócio por parte dos times. | D9: Médio | E9: Média | F9: Para conseguirmos avançar com mais segurança e evitar retrabalho durante o desenvolvimento, acreditamos que seria importante que esses pontos fossem alinhados e consolidados previamente entre os responsáveis pelo negócio. | G9: Time TR | H9: Aberto
A10: RI_06 | B10: Atraso na disponibilização do ambiente de QA | C10: Foi identificada como ponto de atenção a disponibilidade do servidor destinado ao ambiente de QA, necessário para a publicação, validação e homologação da aplicação. | D10: Alto | E10: Alta | F10: Recomenda-se priorizar a disponibilização e configuração do ambiente de QA e, paralelamente, manter o acompanhamento desse ponto junto às equipes envolvidas. Evitando assim, atraso na publicação da aplicação, e possível gargalo no processo de homologação. | G10: Time TR | H10: Aberto

Sheet Fluxos Bizagi
A1: FLUXOS BIZAGI
A4: Seq | B4: ID | C4: Nome | D4: Descrição | E4: Imagem | F4: Status | G4: AtualizadoEm | H4: Passo a Passo
A5: 1 | B5: oportunidade-em-andamento | C5: Oportunidade em Andamento | D5: Fluxo iniciado por agendamento do sistema de contratos; processa oportunidades do Salesforce (Snowflake). | E5: oportunidade-em-andamento.png | F5: Aprovado | G5: 2026-09-18
A6: 2 | B6: new-name | C6: New Name | D6: Fluxo New Name. | E6: new-name.png | F6: Aprovado | G6: 2026-09-18
A7: 3 | B7: new-base-cliente | C7: New Base (Cliente) | D7: Fluxo de nova base de cliente. | E7: new-base-cliente.png | F7: Aprovado | G7: 2026-09-18
A8: 4 | B8: new-base-produto-ou-modulo | C8: New Base (Produto ou Módulo) | D8: Fluxo de nova base de produto ou módulo. | E8: new-base-produto-ou-modulo.png | F8: Aprovado | G8: 2026-09-18
A9: 5 | B9: complementacao-do-contrato | C9: Complementação do Contrato | D9: Fluxo de complementação de dados do contrato. | E9: complementacao-do-contrato.png | F9: Aguardando aprovação | G9: 2026-09-18
A10: 6 | B10: validacao-oportunidades-renovacao | C10: Validação das Oportunidades de Renovação | D10: Fluxo de validação das oportunidades de renovação. | E10: validacao-oportunidades-renovacao.png | F10: Aguardando aprovação | G10: 2026-09-18
A11: 7 | B11: Renovação Anual - Comunicação | C11: Renovação Anual - Comunicação | D11: Renovação Anual - Comunicação | F11: Aguardando aprovação | G11: 2026-09-23
A12: 8 | B12: Cancelamento | C12: Cancelamento | D12: Cancelamento | F12: Em andamento | G12: 2026-09-23
A13: 9 | B13: Entitlement | C13: Entitlement | D13: Entitlement | F13: Nao iniciado | G13: 2026-09-23
A14: 10 | B14: recupera-dados-de-consumo | C14: Recupera Dados de Consumo | D14: Fluxo de recuperação de dados de consumo. | E14: recupera-dados-de-consumo.png | F14: Aguardando aprovação | G14: 2026-09-18
A15: 11 | B15: ausencia-de-consumo | C15: Ausência de Consumo | D15: Fluxo de tratamento de ausência de consumo. | E15: ausencia-de-consumo.png | F15: Aguardando aprovação | G15: 2026-09-18
A16: 12 | B16: excedentes-mensal | C16: Excedentes Mensal | D16: Fluxo de excedentes mensais. | E16: excedentes-mensal.png | F16: Aguardando aprovação | G16: 2026-09-18
A17: 13 | B17: retorno do comunicado do e-mail | C17: retorno do comunicado do e-mail | D17: Fluxo do retorno do comunicado do e-mail | F17: Aguardando aprovação | G17: 2026-09-30
